<?xml version="1.0"?>
<robot name="rover" xmlns:xacro="http://www.ros.org/wiki/xacro">

  <!-- Properties -->
  <xacro:property name="wheel_radius" value="0.05"/>
  <xacro:property name="wheel_separation" value="0.4"/>
  <xacro:property name="wheel_width" value="0.02"/>

  <!-- Base Link -->
  <link name="base_link">
    <visual>
      <geometry>
        <box size="0.5 0.3 0.1"/>
      </geometry>
      <material name="blue">
        <color rgba="0 0 1 1"/>
      </material>
    </visual>
  </link>

  <!-- Wheels -->
  <joint name="left_wheel_joint" type="continuous">
    <parent link="base_link"/>
    <child link="left_wheel"/>
    <origin xyz="-0.2 0.15 0"/>
    <axis xyz="0 1 0"/>
</joint>

<link name="left_wheel">
    <visual>
        <geometry>
            <cylinder length="0.05" radius="0.05"/>
        </geometry>
        <material name="black">
            <color rgba="0 0 0 1"/>
        </material>
    </visual>
</link>

<joint name="right_wheel_joint" type="continuous">
    <parent link="base_link"/>
    <child link="right_wheel"/>
    <origin xyz="-0.2 -0.15 0"/>
    <axis xyz="0 1 0"/>
</joint>

<link name="right_wheel">
    <visual>
        <geometry>
            <cylinder length="0.05" radius="0.05"/>
        </geometry>
        <material name="black">
            <color rgba="0 0 0 1"/>
        </material>
    </visual>
</link>


  <!-- Gazebo Plugin for Differential Drive -->
  <gazebo>
    <plugin name="diff_drive_controller" filename="libgazebo_ros_diff_drive.so">
      <ros>
        <namespace>/</namespace>
      </ros>
      <left_joint>left_wheel_joint</left_joint>
      <right_joint>right_wheel_joint</right_joint>
      <max_wheel_torque>100.0</max_wheel_torque>
      <update_rate>100.0</update_rate>
    </plugin>
  </gazebo>

</robot>
